<?xml version="1.0"?>
<robot name="Scorbot_7">
<link name="table">
    <visual>
      <geometry>
		<mesh filename="file:///home/facu/catkin_ws/src/scorbot/scorbot_7_moveit/modelo/mesa.dae" scale="1 1 1"/>
      </geometry>
    </visual>
  </link>

  <link name="base_link">
    <visual>
      <geometry>
        <mesh filename="file:///home/facu/catkin_ws/src/scorbot/scorbot_7_moveit/modelo/base_robot.dae" scale="1 1 1"/>
      </geometry>
      <origin xyz="0 0 0"/>
    </visual>
  </link>
  
  <joint name="table_to_base" type="fixed">
    <parent link="table"/>
    <child link="base_link"/>
    <origin xyz="0 0 0"/>
  </joint>

<link name="link1">
    <visual>
      <geometry>
        <mesh filename="file:///home/facu/catkin_ws/src/scorbot/scorbot_7_moveit/modelo/link1.dae" scale="1 1 1"/>
      </geometry>
      <origin xyz="0 0 0"/>
    </visual>
  </link>
  
  <joint name="joint1" type="revolute">
    <parent link="base_link"/>
    <child link="link1"/>
    <!--<origin xyz="-0.05 0 -0.378"/>  -->  
    <origin xyz="0 0 0.2"/>   
    <limit effort="1000.0" lower="-2.7" upper="2.7" velocity="0.5"/>
    <axis xyz="0 0 1" />
  </joint>
  
  <link name="link2">
    <visual>
      <geometry>
        <mesh  filename="file:///home/facu/catkin_ws/src/scorbot/scorbot_7_moveit/modelo/link2.dae" scale="1 1 1"/>
      </geometry>
      <origin xyz="0 0 0" rpy="0 0 0" />
      <material name="robot"/>
    </visual>
  </link>

  <joint name="joint2" type="revolute">
    <parent link="link1"/>
    <child link="link2"/>
    <origin xyz="0.05 -0.09 0.158" rpy="0 0 0" />
    <limit effort="1000.0" lower="-1.74" upper="1.22" velocity="0.5"/>
    <axis xyz="0 1 0" />
  </joint>
  
  <link name="link3">
    <visual>
      <geometry>
        <mesh  filename="file:///home/facu/catkin_ws/src/scorbot/scorbot_7_moveit/modelo/link3.dae" scale="1 1 1"/>
      </geometry>
      <origin xyz="0 0 0" rpy="0 0 -1.57" />
      <material name="robot"/>
    </visual>
  </link>

  <joint name="joint3" type="revolute">
    <parent link="link2"/>
    <child link="link3"/>
    <origin xyz="0.3 0 0"/>
    <limit effort="1000.0" lower="-1.74" upper="1.74" velocity="0.5"/>
    <axis xyz="0 1 0" />
  </joint>

  <link name="link4">
    <visual>
      <geometry>
        <mesh  filename="file:///home/facu/catkin_ws/src/scorbot/scorbot_7_moveit/modelo/link4.dae" scale="1 1 1"/>
      </geometry>
      <origin xyz="0 0 0" />
      <material name="robot"/>
    </visual>
  </link>

  <joint name="joint4" type="revolute">
    <parent link="link3"/>
    <child link="link4"/>
    <origin xyz="0.35 0.065 0"/>
    <limit effort="1000.0" lower="-1.57" upper="1.57" velocity="0.5"/>
    <axis xyz="0 1 0" />
  </joint>

  <link name="link5">
    <visual>
      <geometry>
        <mesh  filename="file:///home/facu/catkin_ws/src/scorbot/scorbot_7_moveit/modelo/link5.dae" scale="1 1 1"/>
      </geometry>
      <origin xyz="0 0.001 0" />  <!-- el 0.001 es una correccion -->
      <material name="robot"/>
    </visual>
  </link>

  <joint name="joint5" type="continuous">
    <parent link="link4"/>
    <child link="link5"/>
    <origin xyz="0.14 0 0"/>
    <axis xyz="1 0 0" />
  </joint>
  
<!--  <link name="gripper_pole">
    <visual>
      <geometry>
        <cylinder length="0.2" radius=".01"/>
      </geometry>
      <origin rpy="0 0 0 " xyz="0 0 0"/>
    </visual>
  </link>
  
  <joint name="joint5_prueba" type="fixed">
    <parent link="link5"/>
    <child link="gripper_pole"/>
    <origin xyz="0 0 0"/>
  </joint>
-->
  <link name="left_gripper">
    <visual>
      <origin rpy="0.0 0 0" xyz="0 0 0"/>
      <geometry>
        <mesh filename="package://pr2_description/meshes/gripper_v0/l_finger.dae"/>
      </geometry>
    </visual>
  </link>
  

  <joint name="left_gripper_joint" type="fixed">
    <axis xyz="0 0 1"/>
    <origin rpy="0 0 0" xyz="0 0.01 0"/>
    <parent link="link5"/>
    <child link="left_gripper"/>
  </joint>
  
<!--
  <joint name="left_gripper_joint" type="revolute">
    <axis xyz="0 0 1"/>
    <limit effort="1000.0" lower="0.0" upper="0.548" velocity="0.5"/>
    <origin rpy="0 0 0" xyz="0 0.01 0"/>
    <parent link="link5"/>
    <child link="left_gripper"/>
  </joint>
-->

  <joint name="left_tip_joint" type="fixed">
    <parent link="left_gripper"/>
    <child link="left_tip"/>
  </joint>

  <link name="left_tip">
    <visual>
      <origin rpy="0.0 0 0" xyz="0.09137 0.00495 0"/>
      <geometry>
        <mesh filename="package://pr2_description/meshes/gripper_v0/l_finger_tip.dae"/>
      </geometry>
    </visual>
  </link>

  <joint name="right_gripper_joint" type="fixed">
    <axis xyz="0 0 -1"/>
    <origin rpy="0 0 0" xyz="0 -0.01 0"/>
    <parent link="link5"/>
    <child link="right_gripper"/>
  </joint>
  
<!--
  <joint name="right_gripper_joint" type="revolute">
    <axis xyz="0 0 -1"/>
    <limit effort="1000.0" lower="0.0" upper="0.548" velocity="0.5"/>
    <origin rpy="0 0 0" xyz="0 -0.01 0"/>
    <parent link="link5"/>
    <child link="right_gripper"/>
  </joint>
-->

  <link name="right_gripper">
    <visual>
      <origin rpy="-3.1415 0 0" xyz="0 0 0"/>
      <geometry>
        <mesh filename="package://pr2_description/meshes/gripper_v0/l_finger.dae"/>
      </geometry>
    </visual>
  </link>

  <joint name="right_tip_joint" type="fixed">
    <parent link="right_gripper"/>
    <child link="right_tip"/>
  </joint>

  <link name="right_tip">
    <visual>
      <origin rpy="-3.1415 0 0" xyz="0.09137 0.00495 0"/>
      <geometry>
        <mesh filename="package://pr2_description/meshes/gripper_v0/l_finger_tip.dae"/>
      </geometry>
    </visual>
  </link>
</robot>
